func the_problem_func(): int {
    # This test literally broke because the language is better now.
    # Changed the error thrown.

    # The tracebacks are broken for the moment
    writeln("Look, ma. A TypeError problem!")
    return 2/2
}

func some_other_process() {
    writeln("This doesn't fail yet")
    the_problem_func()
}

func main() {
    writeln("2+2 = ", 2+2)
    some_other_process()
}

writeln("This program should fail with a NameError exception. \nAnd a traceback n.n\n")
main()
